Workbook

Sheet Base de Dados
A7: Categoria | B7: ID da Categoria | C7: SLA | D7: ID do SLA | E7: Nome do Grupo | F7: ID do Grupo | H7: Exporte suas categorias e cole na coluna A, lembrando de exportar com os ID da categoria.
A8: Comunicação e Conectividade > Conectividade de Internet > Bloqueio de Acesso a Sites | B8: 10 | C8: 16 horas | D8: 8 | E8: Segurança da Informação | F8: 2
A9: Comunicação e Conectividade > Conectividade de Internet > Falha de acesso | B9: 12 | C9: 04 horas | D9: 12 | E9: Suporte N1 | F9: 6
A10: Comunicação e Conectividade > Conectividade de Internet > Liberação de Acesso a Sites | B10: 15 | C10: 08 horas | D10: 10 | E10: Segurança da Informação | F10: 2
A11: Comunicação e Conectividade > Serviço de VPN > Configuração de VPN | B11: 9 | C11: 04 horas | D11: 12 | E11: Segurança da Informação | F11: 2
A12: Comunicação e Conectividade > Serviço de VPN > Dúvidas de Conexão de VPN | B12: 3 | C12: 08 horas | D12: 10 | E12: Suporte N1 | F12: 6
A13: Comunicação e Conectividade > Serviço de VPN > Falhas de Acesso a VPN | B13: 25 | C13: 04 horas | D13: 12 | E13: Suporte N1 | F13: 6
A14: Comunicação e Conectividade > Serviços de Colaboração > Configuração de Ambientes de Colaboração | B14: 67 | C14: 08 horas | D14: 10 | E14: Infraestrutura | F14: 3 | H14: Procure no filtro para extração, não trazer as categorias que não são selecionáveis.
A15: Comunicação e Conectividade > Serviços de Colaboração > Dúvidas de Utilização | B15: 90 | C15: 16 horas | D15: 8 | E15: Suporte N1 | F15: 6
A16: Comunicação e Conectividade > Serviços de Colaboração > Falhas de Configuração e Acesso | B16: 34 | C16: 04 horas | D16: 12 | E16: Suporte N1 | F16: 6
A17: Comunicação e Conectividade > Serviços de Colaboração > Integração com Outras Soluções | B17: 13 | C17: 04 horas | D17: 12 | E17: Sistemas | F17: 1
A18: Comunicação e Conectividade > Serviços de E-mail > Configurações Gerais de E-mail | B18: 39 | C18: 16 horas | D18: 8 | E18: Suporte N1 | F18: 6
A19: Comunicação e Conectividade > Serviços de E-mail > Criação de Grupos de E-mail | B19: 19 | C19: 08 horas | D19: 10 | E19: Suporte N1 | F19: 6
A20: Comunicação e Conectividade > Serviços de E-mail > Falha nos Serviços de E-mail | B20: 21 | C20: 04 horas | D20: 12 | E20: Suporte N1 | F20: 6
A21: Comunicação e Conectividade > Serviços de E-mail > Integração de E-mail com Ferramentas de Colaboração | B21: 24 | C21: 08 horas | D21: 10 | E21: Infraestrutura | F21: 3 | H21: Mapeie quais são os SLAs e e Grupos que serão atribuidos a essas categorias, e aplique os Ids nos campos correspondentes
A22: Comunicação e Conectividade > Serviços de Rede > Configuração de Rede Local (LAN) | B22: 18 | C22: 04 horas | D22: 12 | E22: Infraestrutura | F22: 3
A23: Comunicação e Conectividade > Serviços de Rede > Configuração de Rede Sem Fio (Wi-Fi) | B23: 76 | C23: 08 horas | D23: 10 | E23: Infraestrutura | F23: 3
A24: Comunicação e Conectividade > Serviços de Rede > Configuração de Roteadores e Switches | B24: 89 | C24: 08 horas | D24: 10 | E24: Infraestrutura | F24: 3
A25: Comunicação e Conectividade > Serviços de Telefonia > Bloqueio de DDD e DDI | B25: 66 | C25: 04 horas | D25: 12 | E25: Infraestrutura | F25: 3
A26: Comunicação e Conectividade > Serviços de Telefonia > Configuração de Ramal | B26: 14 | C26: 16 horas | D26: 8 | E26: Suporte N1 | F26: 6
A27: Comunicação e Conectividade > Serviços de Telefonia > Configuração de Smartphones | B27: 17 | C27: 24 horas | D27: 4 | E27: Suporte N1 | F27: 6
A28: Comunicação e Conectividade > Serviços de Telefonia > Instalação de Ramal | B28: 11 | C28: 24 horas | D28: 4 | E28: Suporte N1 | F28: 6
A29: Comunicação e Conectividade > Serviços de Telefonia > Liberação de DDD e DDI | B29: 5 | C29: 04 horas | D29: 12 | E29: Infraestrutura | F29: 3
A30: Comunicação e Conectividade > Serviços de Telefonia > Liberação de Smartphone | B30: 27 | C30: 24 horas | D30: 4 | E30: Suporte N1 | F30: 6
A31: Comunicação e Conectividade > Serviços de Telefonia > Ramal com Defeito | B31: 1 | C31: 24 horas | D31: 4 | E31: Suporte N1 | F31: 6
A32: Comunicação e Conectividade > Serviços de Telefonia > Remanejamento de Ponto de Telefone/Ramal | B32: 91 | C32: 24 horas | D32: 4 | E32: Suporte N1 | F32: 6
A33: Comunicação e Conectividade > Serviços de Telefonia > Smartphone Quebrado | B33: 65 | C33: 16 horas | D33: 8 | E33: Suporte N1 | F33: 6
... A36: Comunicação e Conectividade > Serviços de Videoconferência > Suporte Técnico e Manutenção nos Dispositivos de Vídeoconferência | B36: 44 | C36: 16 horas | D36: 8 | E36: Suporte N1 | F36: 6
XFD1048576: Essa planilha foi desenvolvida pela Servicedesk Brasil e sua publicação ou venda é expressamente proíbida.

Sheet Organização
A8: Cole aqui a categoria e separe textos por colunas, aplicando o separador por ">" | G8: Categorias com o texto e espaçamento corrigido
A10: Categoria nível 1 | B10: Categoria nível 2 | C10: Categoria nível 3 | E10: Cole suas categorias na Coluna A, e utilize o Dados > Texto para colunas | G10: Categoria nível 1 | H10: Categoria nível 2 | I10: Categoria nível 3
A11: Comunicação e Conectividade | B11: Conectividade de Internet | C11: Bloqueio de Acesso a Sites | G11: =TRIM(A11) -> Comunicação e Conectividade | H11: =TRIM(B11) -> Conectividade de Internet | I11: =TRIM(C11) -> Bloqueio de Acesso a Sites
A12: Comunicação e Conectividade | B12: Conectividade de Internet | C12: Falha de acesso | G12: =TRIM(A12) -> Comunicação e Conectividade | H12: =TRIM(B12) -> Conectividade de Internet | I12: =TRIM(C12) -> Falha de acesso
A13: Comunicação e Conectividade | B13: Conectividade de Internet | C13: Liberação de Acesso a Sites | G13: =TRIM(A13) -> Comunicação e Conectividade | H13: =TRIM(B13) -> Conectividade de Internet | I13: =TRIM(C13) -> Liberação de Acesso a Sites
A14: Comunicação e Conectividade | B14: Serviço de VPN | C14: Configuração de VPN | G14: =TRIM(A14) -> Comunicação e Conectividade | H14: =TRIM(B14) -> Serviço de VPN | I14: =TRIM(C14) -> Configuração de VPN
A15: Comunicação e Conectividade | B15: Serviço de VPN | C15: Dúvidas de Conexão de VPN | G15: =TRIM(A15) -> Comunicação e Conectividade | H15: =TRIM(B15) -> Serviço de VPN | I15: =TRIM(C15) -> Dúvidas de Conexão de VPN
A16: Comunicação e Conectividade | B16: Serviço de VPN | C16: Falhas de Acesso a VPN | G16: =TRIM(A16) -> Comunicação e Conectividade | H16: =TRIM(B16) -> Serviço de VPN | I16: =TRIM(C16) -> Falhas de Acesso a VPN
A17: Comunicação e Conectividade | B17: Serviços de Colaboração | C17: Configuração de Ambientes de Colaboração | E17: Ao aplicar o separador, vamos notar que o espaço entre a palavra e o ">" foi preservado. Para resolver isso, vamos usar na coluna ao lado a função "=arrumar()" | G17: =TRIM(A17) -> Comunicação e Conectividade | H17: =TRIM(B17) -> Serviços de Colaboração | I17: =TRIM(C17) -> Configuração de Ambientes de Colaboração
A18: Comunicação e Conectividade | B18: Serviços de Colaboração | C18: Dúvidas de Utilização | G18: =TRIM(A18) -> Comunicação e Conectividade | H18: =TRIM(B18) -> Serviços de Colaboração | I18: =TRIM(C18) -> Dúvidas de Utilização
A19: Comunicação e Conectividade | B19: Serviços de Colaboração | C19: Falhas de Configuração e Acesso | G19: =TRIM(A19) -> Comunicação e Conectividade | H19: =TRIM(B19) -> Serviços de Colaboração | I19: =TRIM(C19) -> Falhas de Configuração e Acesso
A20: Comunicação e Conectividade | B20: Serviços de Colaboração | C20: Integração com Outras Soluções | G20: =TRIM(A20) -> Comunicação e Conectividade | H20: =TRIM(B20) -> Serviços de Colaboração | I20: =TRIM(C20) -> Integração com Outras Soluções
A21: Comunicação e Conectividade | B21: Serviços de E-mail | C21: Configurações Gerais de E-mail | G21: =TRIM(A21) -> Comunicação e Conectividade | H21: =TRIM(B21) -> Serviços de E-mail | I21: =TRIM(C21) -> Configurações Gerais de E-mail
A22: Comunicação e Conectividade | B22: Serviços de E-mail | C22: Criação de Grupos de E-mail | G22: =TRIM(A22) -> Comunicação e Conectividade | H22: =TRIM(B22) -> Serviços de E-mail | I22: =TRIM(C22) -> Criação de Grupos de E-mail
A23: Comunicação e Conectividade | B23: Serviços de E-mail | C23: Falha nos Serviços de E-mail | G23: =TRIM(A23) -> Comunicação e Conectividade | H23: =TRIM(B23) -> Serviços de E-mail | I23: =TRIM(C23) -> Falha nos Serviços de E-mail
A24: Comunicação e Conectividade | B24: Serviços de E-mail | C24: Integração de E-mail com Ferramentas de Colaboração | E24: Se você não padronizou seu texto, essa é a hora de utilziar o "=pri.maiuscula()" para adequar o texto com as primeiras letras maiusculas. Ou se preferir tudo minísculo, "=minuscula" | G24: =TRIM(A24) -> Comunicação e Conectividade | H24: =TRIM(B24) -> Serviços de E-mail | I24: =TRIM(C24) -> Integração de E-mail com Ferramentas de Colaboração
A25: Comunicação e Conectividade | B25: Serviços de Rede | C25: Configuração de Rede Local (LAN) | G25: =TRIM(A25) -> Comunicação e Conectividade | H25: =TRIM(B25) -> Serviços de Rede | I25: =TRIM(C25) -> Configuração de Rede Local (LAN)
A26: Comunicação e Conectividade | B26: Serviços de Rede | C26: Configuração de Rede Sem Fio (Wi-Fi) | G26: =TRIM(A26) -> Comunicação e Conectividade | H26: =TRIM(B26) -> Serviços de Rede | I26: =TRIM(C26) -> Configuração de Rede Sem Fio (Wi-Fi)
A27: Comunicação e Conectividade | B27: Serviços de Rede | C27: Configuração de Roteadores e Switches | G27: =TRIM(A27) -> Comunicação e Conectividade | H27: =TRIM(B27) -> Serviços de Rede | I27: =TRIM(C27) -> Configuração de Roteadores e Switches
A28: Comunicação e Conectividade | B28: Serviços de Telefonia | C28: Bloqueio de DDD e DDI | G28: =TRIM(A28) -> Comunicação e Conectividade | H28: =TRIM(B28) -> Serviços de Telefonia | I28: =TRIM(C28) -> Bloqueio de DDD e DDI
A29: Comunicação e Conectividade | B29: Serviços de Telefonia | C29: Configuração de Ramal | G29: =TRIM(A29) -> Comunicação e Conectividade | H29: =TRIM(B29) -> Serviços de Telefonia | I29: =TRIM(C29) -> Configuração de Ramal
A30: Comunicação e Conectividade | B30: Serviços de Telefonia | C30: Configuração de Smartphones | G30: =TRIM(A30) -> Comunicação e Conectividade | H30: =TRIM(B30) -> Serviços de Telefonia | I30: =TRIM(C30) -> Configuração de Smartphones
A31: Comunicação e Conectividade | B31: Serviços de Telefonia | C31: Instalação de Ramal | E31: Repare nas cores aplicadas, elas serão referência para a próxima etapa | G31: =TRIM(A31) -> Comunicação e Conectividade | H31: =TRIM(B31) -> Serviços de Telefonia | I31: =TRIM(C31) -> Instalação de Ramal
A32: Comunicação e Conectividade | B32: Serviços de Telefonia | C32: Liberação de DDD e DDI | G32: =TRIM(A32) -> Comunicação e Conectividade | H32: =TRIM(B32) -> Serviços de Telefonia | I32: =TRIM(C32) -> Liberação de DDD e DDI
A33: Comunicação e Conectividade | B33: Serviços de Telefonia | C33: Liberação de Smartphone | G33: =TRIM(A33) -> Comunicação e Conectividade | H33: =TRIM(B33) -> Serviços de Telefonia | I33: =TRIM(C33) -> Liberação de Smartphone
A34: Comunicação e Conectividade | B34: Serviços de Telefonia | C34: Ramal com Defeito | G34: =TRIM(A34) -> Comunicação e Conectividade | H34: =TRIM(B34) -> Serviços de Telefonia | I34: =TRIM(C34) -> Ramal com Defeito
A35: Comunicação e Conectividade | B35: Serviços de Telefonia | C35: Remanejamento de Ponto de Telefone/Ramal | G35: =TRIM(A35) -> Comunicação e Conectividade | H35: =TRIM(B35) -> Serviços de Telefonia | I35: =TRIM(C35) -> Remanejamento de Ponto de Telefone/Ramal
A36: Comunicação e Conectividade | B36: Serviços de Telefonia | C36: Smartphone Quebrado | G36: =TRIM(A36) -> Comunicação e Conectividade | H36: =TRIM(B36) -> Serviços de Telefonia | I36: =TRIM(C36) -> Smartphone Quebrado
A37: Comunicação e Conectividade | B37: Serviços de Videoconferência | C37: Configuração e Ajustes para Multiconferência | G37: =TRIM(A37) -> Comunicação e Conectividade | H37: =TRIM(B37) -> Serviços de Videoconferência | I37: =TRIM(C37) -> Configuração e Ajustes para Multiconferência
A38: Comunicação e Conectividade | B38: Serviços de Videoconferência | C38: Dúvidas de Utilização | G38: =TRIM(A38) -> Comunicação e Conectividade | H38: =TRIM(B38) -> Serviços de Videoconferência | I38: =TRIM(C38) -> Dúvidas de Utilização
A39: Comunicação e Conectividade | B39: Serviços de Videoconferência | C39: Suporte Técnico e Manutenção nos Dispositivos de Vídeoconferência | G39: =TRIM(A39) -> Comunicação e Conectividade | H39: =TRIM(B39) -> Serviços de Videoconferência | I39: =TRIM(C39) -> Suporte Técnico e Manutenção nos Dispositivos de Vídeoconferência
XFD1048576: Essa planilha foi desenvolvida pela Servicedesk Brasil e sua publicação ou venda é expressamente proíbida.

Sheet Regras de Categorização
AI7: insert into glpi_rules
A8: Primeiramente tenha certeza sobre úlitmo ID de regra válido, para isso realize a consulta "SELECT id FROM glpi_rules ORDER BY id DESC LIMIT 1" | G8: Saiba para qual entidade irá criar as regras, o ID da entidade vai no campo entities_id | M8: ( | N8: id | O8: , | P8: entities_id | Q8: , | R8: sub_type | S8: , | T8: ranking | U8: , | V8: name | X8: , | Y8: description | Z8: , | AA8: `match` | AB8: , | AC8: is_active | AD8: , | AE8: is_recursive | AF8: , | AG8: condition | AH8: ) | AI8: =_xlfn.CONCAT(M8:AH8) -> (id,entities_id,sub_type,ranking,name,description,`match`,is_active,is_recursive,condition)
AI9: Values
M10: ( | N10: 100 | O10: , | P10: 0 | Q10: ,' | R10: RuleTicket' | S10: , | T10: 10 | U10: ,' | V10: Formulário x Descrição x Categoria | W10: ='Base de Dados'!A8 -> Comunicação e Conectividade > Conectividade de Internet > Bloqueio de Acesso a Sites | X10: ',' | Y10: regra para categoriação do chamado com base no texto da descrição' | Z10: ,' | AA10: AND' | AB10: , | AC10: 1 | AD10: , | AE10: 1 | AF10: , | AG10: 1 | AH10: ), | AI10: =_xlfn.CONCAT(M10:AH10) -> (100,0,'RuleTicket',10,'Formulário x Descrição x Categoria Comunicação e Conectividade > Conectividade de Internet > Bloqueio de Acesso a Sites ','regra para categoriação do chamado com base no texto da descrição','AND',1,1,1),
M11: ( | N11: =N10+1 -> 101 | O11: , | P11: 0 | Q11: ,' | R11: RuleTicket' | S11: , | T11: =T10+1 -> 11 | U11: ,' | V11: Formulário x Descrição x Categoria | W11: ='Base de Dados'!A9 -> Comunicação e Conectividade > Conectividade de Internet > Falha de acesso | X11: ',' | Y11: regra para categoriação do chamado com base no texto da descrição' | Z11: ,' | AA11: AND' | AB11: , | AC11: 1 | AD11: , | AE11: 1 | AF11: , | AG11: 1 | AH11: ), | AI11: =_xlfn.CONCAT(M11:AH11) -> (101,0,'RuleTicket',11,'Formulário x Descrição x Categoria Comunicação e Conectividade > Conectividade de Internet > Falha de acesso ','regra para categoriação do chamado com base no texto da descrição','AND',1,1,1),
M12: ( | N12: =N11+1 -> 102 | O12: , | P12: 0 | Q12: ,' | R12: RuleTicket' | S12: , | T12: =T11+1 -> 12 | U12: ,' | V12: Formulário x Descrição x Categoria | W12: ='Base de Dados'!A10 -> Comunicação e Conectividade > Conectividade de Internet > Liberação de Acesso a Sites | X12: ',' | Y12: regra para categoriação do chamado com base no texto da descrição' | Z12: ,' | AA12: AND' | AB12: , | AC12: 1 | AD12: , | AE12: 1 | AF12: , | AG12: 1 | AH12: ), | AI12: =_xlfn.CONCAT(M12:AH12) -> (102,0,'RuleTicket',12,'Formulário x Descrição x Categoria Comunicação e Conectividade > Conectividade de Internet > Liberação de Acesso a Sites ','regra para categoriação do chamado com base no texto da descrição','AND',1,1,1),
M13: ( | N13: =N12+1 -> 103 | O13: , | P13: 0 | Q13: ,' | R13: RuleTicket' | S13: , | T13: =T12+1 -> 13 | U13: ,' | V13: Formulário x Descrição x Categoria | W13: ='Base de Dados'!A11 -> Comunicação e Conectividade > Serviço de VPN > Configuração de VPN | X13: ',' | Y13: regra para categoriação do chamado com base no texto da descrição' | Z13: ,' | AA13: AND' | AB13: , | AC13: 1 | AD13: , | AE13: 1 | AF13: , | AG13: 1 | AH13: ), | AI13: =_xlfn.CONCAT(M13:AH13) -> (103,0,'RuleTicket',13,'Formulário x Descrição x Categoria Comunicação e Conectividade > Serviço de VPN > Configuração de VPN ','regra para categoriação do chamado com base no texto da descrição','AND',1,1,1),
M14: ( | N14: =N13+1 -> 104 | O14: , | P14: 0 | Q14: ,' | R14: RuleTicket' | S14: , | T14: =T13+1 -> 14 | U14: ,' | V14: Formulário x Descrição x Categoria | W14: ='Base de Dados'!A12 -> Comunicação e Conectividade > Serviço de VPN > Dúvidas de Conexão de VPN | X14: ',' | Y14: regra para categoriação do chamado com base no texto da descrição' | Z14: ,' | AA14: AND' | AB14: , | AC14: 1 | AD14: , | AE14: 1 | AF14: , | AG14: 1 | AH14: ), | AI14: =_xlfn.CONCAT(M14:AH14) -> (104,0,'RuleTicket',14,'Formulário x Descrição x Categoria Comunicação e Conectividade > Serviço de VPN > Dúvidas de Conexão de VPN ','regra para categoriação do chamado com base no texto da descrição','AND',1,1,1),
M15: ( | N15: =N14+1 -> 105 | O15: , | P15: 0 | Q15: ,' | R15: RuleTicket' | S15: , | T15: =T14+1 -> 15 | U15: ,' | V15: Formulário x Descrição x Categoria | W15: ='Base de Dados'!A13 -> Comunicação e Conectividade > Serviço de VPN > Falhas de Acesso a VPN | X15: ',' | Y15: regra para categoriação do chamado com base no texto da descrição' | Z15: ,' | AA15: AND' | AB15: , | AC15: 1 | AD15: , | AE15: 1 | AF15: , | AG15: 1 | AH15: ), | AI15: =_xlfn.CONCAT(M15:AH15) -> (105,0,'RuleTicket',15,'Formulário x Descrição x Categoria Comunicação e Conectividade > Serviço de VPN > Falhas de Acesso a VPN ','regra para categoriação do chamado com base no texto da descrição','AND',1,1,1),
M16: ( | N16: =N15+1 -> 106 | O16: , | P16: 0 | Q16: ,' | R16: RuleTicket' | S16: , | T16: =T15+1 -> 16 | U16: ,' | V16: Formulário x Descrição x Categoria | W16: ='Base de Dados'!A14 -> Comunicação e Conectividade > Serviços de Colaboração > Configuração de Ambientes de Colaboração | X16: ',' | Y16: regra para categoriação do chamado com base no texto da descrição' | Z16: ,' | AA16: AND' | AB16: , | AC16: 1 | AD16: , | AE16: 1 | AF16: , | AG16: 1 | AH16: ), | AI16: =_xlfn.CONCAT(M16:AH16) -> (106,0,'RuleTicket',16,'Formulário x Descrição x Categoria Comunicação e Conectividade > Serviços de Colaboração > Configuração de Ambientes de Colaboração ','regra para categoriação do chamado com base no texto da descrição','AND',1,1,1),
A17: O Sub_Type das regras é dividido em Regras de Chamados "RuleTicket", Regras de Autenticação "RuleRight", Regras para coleta por e-mail "RuleMailCollector", para mais regras consulte a tabela glpi_rules | G17: Ranking é a posição em que a regras estará na listagem, o que importante para definir o funcionamento da execução das automações. Para consultar o último numero do ranking execute a consulta "SELECT ranking "FROM glpi_rules ORDER BY ranking DESC LIMIT 1" | M17: ( | N17: =N16+1 -> 107 | O17: , | P17: 0 | Q17: ,' | R17: RuleTicket' | S17: , | T17: =T16+1 -> 17 | U17: ,' | V17: Formulário x Descrição x Categoria | W17: ='Base de Dados'!A15 -> Comunicação e Conectividade > Serviços de Colaboração > Dúvidas de Utilização | X17: ',' | Y17: regra para categoriação do chamado com base no texto da descrição' | Z17: ,' | AA17: AND' | AB17: , | AC17: 1 | AD17: , | AE17: 1 | AF17: , | AG17: 1 | AH17: ), | AI17: =_xlfn.CONCAT(M17:AH17) -> (107,0,'RuleTicket',17,'Formulário x Descrição x Categoria Comunicação e Conectividade > Serviços de Colaboração > Dúvidas de Utilização ','regra para categoriação do chamado com base no texto da descrição','AND',1,1,1),
M18: ( | N18: =N17+1 -> 108 | O18: , | P18: 0 | Q18: ,' | R18: RuleTicket' | S18: , | T18: =T17+1 -> 18 | U18: ,' | V18: Formulário x Descrição x Categoria | W18: ='Base de Dados'!A16 -> Comunicação e Conectividade > Serviços de Colaboração > Falhas de Configuração e Acesso | X18: ',' | Y18: regra para categoriação do chamado com base no texto da descrição' | Z18: ,' | AA18: AND' | AB18: , | AC18: 1 | AD18: , | AE18: 1 | AF18: , | AG18: 1 | AH18: ), | AI18: =_xlfn.CONCAT(M18:AH18) -> (108,0,'RuleTicket',18,'Formulário x Descrição x Categoria Comunicação e Conectividade > Serviços de Colaboração > Falhas de Configuração e Acesso ','regra para categoriação do chamado com base no texto da descrição','AND',1,1,1),
M19: ( | N19: =N18+1 -> 109 | O19: , | P19: 0 | Q19: ,' | R19: RuleTicket' | S19: , | T19: =T18+1 -> 19 | U19: ,' | V19: Formulário x Descrição x Categoria | W19: ='Base de Dados'!A17 -> Comunicação e Conectividade > Serviços de Colaboração > Integração com Outras Soluções | X19: ',' | Y19: regra para categoriação do chamado com base no texto da descrição' | Z19: ,' | AA19: AND' | AB19: , | AC19: 1 | AD19: , | AE19: 1 | AF19: , | AG19: 1 | AH19: ), | AI19: =_xlfn.CONCAT(M19:AH19) -> (109,0,'RuleTicket',19,'Formulário x Descrição x Categoria Comunicação e Conectividade > Serviços de Colaboração > Integração com Outras Soluções ','regra para categoriação do chamado com base no texto da descrição','AND',1,1,1),
M20: ( | N20: =N19+1 -> 110 | O20: , | P20: 0 | Q20: ,' | R20: RuleTicket' | S20: , | T20: =T19+1 -> 20 | U20: ,' | V20: Formulário x Descrição x Categoria | W20: ='Base de Dados'!A18 -> Comunicação e Conectividade > Serviços de E-mail > Configurações Gerais de E-mail | X20: ',' | Y20: regra para categoriação do chamado com base no texto da descrição' | Z20: ,' | AA20: AND' | AB20: , | AC20: 1 | AD20: , | AE20: 1 | AF20: , | AG20: 1 | AH20: ), | AI20: =_xlfn.CONCAT(M20:AH20) -> (110,0,'RuleTicket',20,'Formulário x Descrição x Categoria Comunicação e Conectividade > Serviços de E-mail > Configurações Gerais de E-mail ','regra para categoriação do chamado com base no texto da descrição','AND',1,1,1),
M21: ( | N21: =N20+1 -> 111 | O21: , | P21: 0 | Q21: ,' | R21: RuleTicket' | S21: , | T21: =T20+1 -> 21 | U21: ,' | V21: Formulário x Descrição x Categoria | W21: ='Base de Dados'!A19 -> Comunicação e Conectividade > Serviços de E-mail > Criação de Grupos de E-mail | X21: ',' | Y21: regra para categoriação do chamado com base no texto da descrição' | Z21: ,' | AA21: AND' | AB21: , | AC21: 1 | AD21: , | AE21: 1 | AF21: , | AG21: 1 | AH21: ), | AI21: =_xlfn.CONCAT(M21:AH21) -> (111,0,'RuleTicket',21,'Formulário x Descrição x Categoria Comunicação e Conectividade > Serviços de E-mail > Criação de Grupos de E-mail ','regra para categoriação do chamado com base no texto da descrição','AND',1,1,1),
M22: ( | N22: =N21+1 -> 112 | O22: , | P22: 0 | Q22: ,' | R22: RuleTicket' | S22: , | T22: =T21+1 -> 22 | U22: ,' | V22: Formulário x Descrição x Categoria | W22: ='Base de Dados'!A20 -> Comunicação e Conectividade > Serviços de E-mail > Falha nos Serviços de E-mail | X22: ',' | Y22: regra para categoriação do chamado com base no texto da descrição' | Z22: ,' | AA22: AND' | AB22: , | AC22: 1 | AD22: , | AE22: 1 | AF22: , | AG22: 1 | AH22: ), | AI22: =_xlfn.CONCAT(M22:AH22) -> (112,0,'RuleTicket',22,'Formulário x Descrição x Categoria Comunicação e Conectividade > Serviços de E-mail > Falha nos Serviços de E-mail ','regra para categoriação do chamado com base no texto da descrição','AND',1,1,1),
M23: ( | N23: =N22+1 -> 113 | O23: , | P23: 0 | Q23: ,' | R23: RuleTicket' | S23: , | T23: =T22+1 -> 23 | U23: ,' | V23: Formulário x Descrição x Categoria | W23: ='Base de Dados'!A21 -> Comunicação e Conectividade > Serviços de E-mail > Integração de E-mail com Ferramentas de Colaboração | X23: ',' | Y23: regra para categoriação do chamado com base no texto da descrição' | Z23: ,' | AA23: AND' | AB23: , | AC23: 1 | AD23: , | AE23: 1 | AF23: , | AG23: 1 | AH23: ), | AI23: =_xlfn.CONCAT(M23:AH23) -> (113,0,'RuleTicket',23,'Formulário x Descrição x Categoria Comunicação e Conectividade > Serviços de E-mail > Integração de E-mail com Ferramentas de Colaboração ','regra para categoriação do chamado com base no texto da descrição','AND',1,1,1),
M24: ( | N24: =N23+1 -> 114 | O24: , | P24: 0 | Q24: ,' | R24: RuleTicket' | S24: , | T24: =T23+1 -> 24 | U24: ,' | V24: Formulário x Descrição x Categoria | W24: ='Base de Dados'!A22 -> Comunicação e Conectividade > Serviços de Rede > Configuração de Rede Local (LAN) | X24: ',' | Y24: regra para categoriação do chamado com base no texto da descrição' | Z24: ,' | AA24: AND' | AB24: , | AC24: 1 | AD24: , | AE24: 1 | AF24: , | AG24: 1 | AH24: ), | AI24: =_xlfn.CONCAT(M24:AH24) -> (114,0,'RuleTicket',24,'Formulário x Descrição x Categoria Comunicação e Conectividade > Serviços de Rede > Configuração de Rede Local (LAN) ','regra para categoriação do chamado com base no texto da descrição','AND',1,1,1),
A25: Para a categorização dos chamados, vamos usar uma nomenclatura que indique que o chamado veio do Formulário e vamos com base nas descrição encontrar a categoria, dessa forma a primera parte do nome será uma constante, e a segunda irá variar conforme o conteúdo na aba Organização | G25: Match são os operadores lógicos E e OU, representados respectivamente por "AND" e "OR" | M25: ( | N25: =N24+1 -> 115 | O25: , | P25: 0 | Q25: ,' | R25: RuleTicket' | S25: , | T25: =T24+1 -> 25 | U25: ,' | V25: Formulário x Descrição x Categoria | W25: ='Base de Dados'!A23 -> Comunicação e Conectividade > Serviços de Rede > Configuração de Rede Sem Fio (Wi-Fi) | X25: ',' | Y25: regra para categoriação do chamado com base no texto da descrição' | Z25: ,' | AA25: AND' | AB25: , | AC25: 1 | AD25: , | AE25: 1 | AF25: , | AG25: 1 | AH25: ), | AI25: =_xlfn.CONCAT(M25:AH25) -> (115,0,'RuleTicket',25,'Formulário x Descrição x Categoria Comunicação e Conectividade > Serviços de Rede > Configuração de Rede Sem Fio (Wi-Fi) ','regra para categoriação do chamado com base no texto da descrição','AND',1,1,1),
M26: ( | N26: =N25+1 -> 116 | O26: , | P26: 0 | Q26: ,' | R26: RuleTicket' | S26: , | T26: =T25+1 -> 26 | U26: ,' | V26: Formulário x Descrição x Categoria | W26: ='Base de Dados'!A24 -> Comunicação e Conectividade > Serviços de Rede > Configuração de Roteadores e Switches | X26: ',' | Y26: regra para categoriação do chamado com base no texto da descrição' | Z26: ,' | AA26: AND' | AB26: , | AC26: 1 | AD26: , | AE26: 1 | AF26: , | AG26: 1 | AH26: ), | AI26: =_xlfn.CONCAT(M26:AH26) -> (116,0,'RuleTicket',26,'Formulário x Descrição x Categoria Comunicação e Conectividade > Serviços de Rede > Configuração de Roteadores e Switches ','regra para categoriação do chamado com base no texto da descrição','AND',1,1,1),
M27: ( | N27: =N26+1 -> 117 | O27: , | P27: 0 | Q27: ,' | R27: RuleTicket' | S27: , | T27: =T26+1 -> 27 | U27: ,' | V27: Formulário x Descrição x Categoria | W27: ='Base de Dados'!A25 -> Comunicação e Conectividade > Serviços de Telefonia > Bloqueio de DDD e DDI | X27: ',' | Y27: regra para categoriação do chamado com base no texto da descrição' | Z27: ,' | AA27: AND' | AB27: , | AC27: 1 | AD27: , | AE27: 1 | AF27: , | AG27: 1 | AH27: ), | AI27: =_xlfn.CONCAT(M27:AH27) -> (117,0,'RuleTicket',27,'Formulário x Descrição x Categoria Comunicação e Conectividade > Serviços de Telefonia > Bloqueio de DDD e DDI ','regra para categoriação do chamado com base no texto da descrição','AND',1,1,1),
M28: ( | N28: =N27+1 -> 118 | O28: , | P28: 0 | Q28: ,' | R28: RuleTicket' | S28: , | T28: =T27+1 -> 28 | U28: ,' | V28: Formulário x Descrição x Categoria | W28: ='Base de Dados'!A26 -> Comunicação e Conectividade > Serviços de Telefonia > Configuração de Ramal | X28: ',' | Y28: regra para categoriação do chamado com base no texto da descrição' | Z28: ,' | AA28: AND' | AB28: , | AC28: 1 | AD28: , | AE28: 1 | AF28: , | AG28: 1 | AH28: ), | AI28: =_xlfn.CONCAT(M28:AH28) -> (118,0,'RuleTicket',28,'Formulário x Descrição x Categoria Comunicação e Conectividade > Serviços de Telefonia > Configuração de Ramal ','regra para categoriação do chamado com base no texto da descrição','AND',1,1,1),
M29: ( | N29: =N28+1 -> 119 | O29: , | P29: 0 | Q29: ,' | R29: RuleTicket' | S29: , | T29: =T28+1 -> 29 | U29: ,' | V29: Formulário x Descrição x Categoria | W29: ='Base de Dados'!A27 -> Comunicação e Conectividade > Serviços de Telefonia > Configuração de Smartphones | X29: ',' | Y29: regra para categoriação do chamado com base no texto da descrição' | Z29: ,' | AA29: AND' | AB29: , | AC29: 1 | AD29: , | AE29: 1 | AF29: , | AG29: 1 | AH29: ), | AI29: =_xlfn.CONCAT(M29:AH29) -> (119,0,'RuleTicket',29,'Formulário x Descrição x Categoria Comunicação e Conectividade > Serviços de Telefonia > Configuração de Smartphones ','regra para categoriação do chamado com base no texto da descrição','AND',1,1,1),
M30: ( | N30: =N29+1 -> 120 | O30: , | P30: 0 | Q30: ,' | R30: RuleTicket' | S30: , | T30: =T29+1 -> 30 | U30: ,' | V30: Formulário x Descrição x Categoria | W30: ='Base de Dados'!A28 -> Comunicação e Conectividade > Serviços de Telefonia > Instalação de Ramal | X30: ',' | Y30: regra para categoriação do chamado com base no texto da descrição' | Z30: ,' | AA30: AND' | AB30: , | AC30: 1 | AD30: , | AE30: 1 | AF30: , | AG30: 1 | AH30: ), | AI30: =_xlfn.CONCAT(M30:AH30) -> (120,0,'RuleTicket',30,'Formulário x Descrição x Categoria Comunicação e Conectividade > Serviços de Telefonia > Instalação de Ramal ','regra para categoriação do chamado com base no texto da descrição','AND',1,1,1),
M31: ( | N31: =N30+1 -> 121 | O31: , | P31: 0 | Q31: ,' | R31: RuleTicket' | S31: , | T31: =T30+1 -> 31 | U31: ,' | V31: Formulário x Descrição x Categoria | W31: ='Base de Dados'!A29 -> Comunicação e Conectividade > Serviços de Telefonia > Liberação de DDD e DDI | X31: ',' | Y31: regra para categoriação do chamado com base no texto da descrição' | Z31: ,' | AA31: AND' | AB31: , | AC31: 1 | AD31: , | AE31: 1 | AF31: , | AG31: 1 | AH31: ), | AI31: =_xlfn.CONCAT(M31:AH31) -> (121,0,'RuleTicket',31,'Formulário x Descrição x Categoria Comunicação e Conectividade > Serviços de Telefonia > Liberação de DDD e DDI ','regra para categoriação do chamado com base no texto da descrição','AND',1,1,1),
M32: ( | N32: =N31+1 -> 122 | O32: , | P32: 0 | Q32: ,' | R32: RuleTicket' | S32: , | T32: =T31+1 -> 32 | U32: ,' | V32: Formulário x Descrição x Categoria | W32: ='Base de Dados'!A30 -> Comunicação e Conectividade > Serviços de Telefonia > Liberação de Smartphone | X32: ',' | Y32: regra para categoriação do chamado com base no texto da descrição' | Z32: ,' | AA32: AND' | AB32: , | AC32: 1 | AD32: , | AE32: 1 | AF32: , | AG32: 1 | AH32: ), | AI32: =_xlfn.CONCAT(M32:AH32) -> (122,0,'RuleTicket',32,'Formulário x Descrição x Categoria Comunicação e Conectividade > Serviços de Telefonia > Liberação de Smartphone ','regra para categoriação do chamado com base no texto da descrição','AND',1,1,1),
A33: Is_Active e Is_Recursive são usados para regras com status Ativo Sim ou Ativo Não, e Recursividade para as entidades abaixo. Onde 0 é não e 1 é sim | G33: Condition é o tipo de execução da regra, apenas na Adição do chamado, apenas na Atualização do chamado, ou em ambos, Adicionar/Atualizar, e são representados respectivamente por 1,2 e 3. | M33: ( | N33: =N32+1 -> 123 | O33: , | P33: 0 | Q33: ,' | R33: RuleTicket' | S33: , | T33: =T32+1 -> 33 | U33: ,' | V33: Formulário x Descrição x Categoria | W33: ='Base de Dados'!A31 -> Comunicação e Conectividade > Serviços de Telefonia > Ramal com Defeito | X33: ',' | Y33: regra para categoriação do chamado com base no texto da descrição' | Z33: ,' | AA33: AND' | AB33: , | AC33: 1 | AD33: , | AE33: 1 | AF33: , | AG33: 1 | AH33: ), | AI33: =_xlfn.CONCAT(M33:AH33) -> (123,0,'RuleTicket',33,'Formulário x Descrição x Categoria Comunicação e Conectividade > Serviços de Telefonia > Ramal com Defeito ','regra para categoriação do chamado com base no texto da descrição','AND',1,1,1),
M34: ( | N34: =N33+1 -> 124 | O34: , | P34: 0 | Q34: ,' | R34: RuleTicket' | S34: , | T34: =T33+1 -> 34 | U34: ,' | V34: Formulário x Descrição x Categoria | W34: ='Base de Dados'!A32 -> Comunicação e Conectividade > Serviços de Telefonia > Remanejamento de Ponto de Telefone/Ramal | X34: ',' | Y34: regra para categoriação do chamado com base no texto da descrição' | Z34: ,' | AA34: AND' | AB34: , | AC34: 1 | AD34: , | AE34: 1 | AF34: , | AG34: 1 | AH34: ), | AI34: =_xlfn.CONCAT(M34:AH34) -> (124,0,'RuleTicket',34,'Formulário x Descrição x Categoria Comunicação e Conectividade > Serviços de Telefonia > Remanejamento de Ponto de Telefone/Ramal ','regra para categoriação do chamado com base no texto da descrição','AND',1,1,1),
M35: ( | N35: =N34+1 -> 125 | O35: , | P35: 0 | Q35: ,' | R35: RuleTicket' | S35: , | T35: =T34+1 -> 35 | U35: ,' | V35: Formulário x Descrição x Categoria | W35: ='Base de Dados'!A33 -> Comunicação e Conectividade > Serviços de Telefonia > Smartphone Quebrado | X35: ',' | Y35: regra para categoriação do chamado com base no texto da descrição' | Z35: ,' | AA35: AND' | AB35: , | AC35: 1 | AD35: , | AE35: 1 | AF35: , | AG35: 1 | AH35: ), | AI35: =_xlfn.CONCAT(M35:AH35) -> (125,0,'RuleTicket',35,'Formulário x Descrição x Categoria Comunicação e Conectividade > Serviços de Telefonia > Smartphone Quebrado ','regra para categoriação do chamado com base no texto da descrição','AND',1,1,1),
M36: ( | N36: =N35+1 -> 126 | O36: , | P36: 0 | Q36: ,' | R36: RuleTicket' | S36: , | T36: =T35+1 -> 36 | U36: ,' | V36: Formulário x Descrição x Categoria | W36: ='Base de Dados'!A34 -> Comunicação e Conectividade > Serviços de Videoconferência > Configuração e Ajustes para Multiconferência | X36: ',' | Y36: regra para categoriação do chamado com base no texto da descrição' | Z36: ,' | AA36: AND' | AB36: , | AC36: 1 | AD36: , | AE36: 1 | AF36: , | AG36: 1 | AH36: ), | AI36: =_xlfn.CONCAT(M36:AH36) -> (126,0,'RuleTicket',36,'Formulário x Descrição x Categoria Comunicação e Conectividade > Serviços de Videoconferência > Configuração e Ajustes para Multiconferência ','regra para categoriação do chamado com base no texto da descrição','AND',1,1,1),
M37: ( | N37: =N36+1 -> 127 | O37: , | P37: 0 | Q37: ,' | R37: RuleTicket' | S37: , | T37: =T36+1 -> 37 | U37: ,' | V37: Formulário x Descrição x Categoria | W37: ='Base de Dados'!A35 -> Comunicação e Conectividade > Serviços de Videoconferência > Dúvidas de Utilização | X37: ',' | Y37: regra para categoriação do chamado com base no texto da descrição' | Z37: ,' | AA37: AND' | AB37: , | AC37: 1 | AD37: , | AE37: 1 | AF37: , | AG37: 1 | AH37: ), | AI37: =_xlfn.CONCAT(M37:AH37) -> (127,0,'RuleTicket',37,'Formulário x Descrição x Categoria Comunicação e Conectividade > Serviços de Videoconferência > Dúvidas de Utilização ','regra para categoriação do chamado com base no texto da descrição','AND',1,1,1),
M38: ( | N38: =N37+1 -> 128 | O38: , | P38: 0 | Q38: ,' | R38: RuleTicket' | S38: , | T38: =T37+1 -> 38 | U38: ,' | V38: Formulário x Descrição x Categoria | W38: ='Base de Dados'!A36 -> Comunicação e Conectividade > Serviços de Videoconferência > Suporte Técnico e Manutenção nos Dispositivos de Vídeoconferência | X38: ',' | Y38: regra para categoriação do chamado com base no texto da descrição' | Z38: ,' | AA38: AND' | AB38: , | AC38: 1 | AD38: , | AE38: 1 | AF38: , | AG38: 1 | AH38: ) | AI38: =_xlfn.CONCAT(M38:AH38) -> (128,0,'RuleTicket',38,'Formulário x Descrição x Categoria Comunicação e Conectividade > Serviços de Videoconferência > Suporte Técnico e Manutenção nos Dispositivos de Vídeoconferência ','regra para categoriação do chamado com base no texto da descrição','AND',1,1,1)
AA40: Sempre na última linha de comando do script, remova a "," para que o MySQL entenda que terminou a instrução. | AI40: Copie o insert acima no seu SQL, lembre-se de sempre ter realizado um backup antes, seja da tabela ou do banco de dados inteiro. Antes de executar dê o comando crtl+F para abrir a janela de pesquisa e substituição. Substitua " '," (espaço+apostrofe+virgula), por "'," (apostrofe+virgula). Removendo o espaço que ficou entre o final do nome da regra e a próxima instrução.
XFD1048576: Essa planilha foi desenvolvida pela Servicedesk Brasil e sua publicação ou venda é expressamente proíbida.

Sheet Critérios
V7: Insert into glpi_rulecriterias
A8: Vamos aplicar os critérios em ordem do primeiro critério para todas as regras, depois o segundo critério, o terceiro e assim sucessivamente. | G8: Não vamos utilziar o ID do critéiro, mas o ID de referênca da regra (rules_id) | M8: ( | N8: rule_id | O8: , | P8: critéria | Q8: , | R8: condition | S8: , | T8: pattern | U8: ) | V8: =_xlfn.CONCAT(M8:U8) -> (rule_id,critéria,condition,pattern)
V9: values
M10: ( | N10: ='Regras de Categorização'!N10 -> 100 | O10: ,' | P10: name' | Q10: , | R10: 2 | S10: ,' | T10: =Organização!G11 -> Comunicação e Conectividade | U10: '), | V10: =_xlfn.CONCAT(M10:U10) -> (100,'name',2,'Comunicação e Conectividade '),
M11: ( | N11: ='Regras de Categorização'!N11 -> 101 | O11: ,' | P11: name' | Q11: , | R11: 2 | S11: ,' | T11: =Organização!G12 -> Comunicação e Conectividade | U11: '), | V11: =_xlfn.CONCAT(M11:U11) -> (101,'name',2,'Comunicação e Conectividade '),
M12: ( | N12: ='Regras de Categorização'!N12 -> 102 | O12: ,' | P12: name' | Q12: , | R12: 2 | S12: ,' | T12: =Organização!G13 -> Comunicação e Conectividade | U12: '), | V12: =_xlfn.CONCAT(M12:U12) -> (102,'name',2,'Comunicação e Conectividade '),
M13: ( | N13: ='Regras de Categorização'!N13 -> 103 | O13: ,' | P13: name' | Q13: , | R13: 2 | S13: ,' | T13: =Organização!G14 -> Comunicação e Conectividade | U13: '), | V13: =_xlfn.CONCAT(M13:U13) -> (103,'name',2,'Comunicação e Conectividade '),
M14: ( | N14: ='Regras de Categorização'!N14 -> 104 | O14: ,' | P14: name' | Q14: , | R14: 2 | S14: ,' | T14: =Organização!G15 -> Comunicação e Conectividade | U14: '), | V14: =_xlfn.CONCAT(M14:U14) -> (104,'name',2,'Comunicação e Conectividade '),
M15: ( | N15: ='Regras de Categorização'!N15 -> 105 | O15: ,' | P15: name' | Q15: , | R15: 2 | S15: ,' | T15: =Organização!G16 -> Comunicação e Conectividade | U15: '), | V15: =_xlfn.CONCAT(M15:U15) -> (105,'name',2,'Comunicação e Conectividade '),
M16: ( | N16: ='Regras de Categorização'!N16 -> 106 | O16: ,' | P16: name' | Q16: , | R16: 2 | S16: ,' | T16: =Organização!G17 -> Comunicação e Conectividade | U16: '), | V16: =_xlfn.CONCAT(M16:U16) -> (106,'name',2,'Comunicação e Conectividade '),
A17: Critéria é o tipo de critério que vamos utilizar, por exemplo o campo descrição, então critéria será "content", para título usamos "name", para as demais possibilidades, com o banco aberto vá aplicando um critério e lendo no banco qual o nome utilizado. Não tem atalho! | G17: Condition é a condição do critéiro, É, Não É, Contém, Não Contém, etc. o ID seguirá a mesma ordem de exibição na página, sendo É=0, Não É=1, Contém=2, Não Contém=3, etc. | M17: ( | N17: ='Regras de Categorização'!N17 -> 107 | O17: ,' | P17: name' | Q17: , | R17: 2 | S17: ,' | T17: =Organização!G18 -> Comunicação e Conectividade | U17: '), | V17: =_xlfn.CONCAT(M17:U17) -> (107,'name',2,'Comunicação e Conectividade '),
M18: ( | N18: ='Regras de Categorização'!N18 -> 108 | O18: ,' | P18: name' | Q18: , | R18: 2 | S18: ,' | T18: =Organização!G19 -> Comunicação e Conectividade | U18: '), | V18: =_xlfn.CONCAT(M18:U18) -> (108,'name',2,'Comunicação e Conectividade '),
M19: ( | N19: ='Regras de Categorização'!N19 -> 109 | O19: ,' | P19: name' | Q19: , | R19: 2 | S19: ,' | T19: =Organização!G20 -> Comunicação e Conectividade | U19: '), | V19: =_xlfn.CONCAT(M19:U19) -> (109,'name',2,'Comunicação e Conectividade '),
M20: ( | N20: ='Regras de Categorização'!N20 -> 110 | O20: ,' | P20: name' | Q20: , | R20: 2 | S20: ,' | T20: =Organização!G21 -> Comunicação e Conectividade | U20: '), | V20: =_xlfn.CONCAT(M20:U20) -> (110,'name',2,'Comunicação e Conectividade '),
M21: ( | N21: ='Regras de Categorização'!N21 -> 111 | O21: ,' | P21: name' | Q21: , | R21: 2 | S21: ,' | T21: =Organização!G22 -> Comunicação e Conectividade | U21: '), | V21: =_xlfn.CONCAT(M21:U21) -> (111,'name',2,'Comunicação e Conectividade '),
M22: ( | N22: ='Regras de Categorização'!N22 -> 112 | O22: ,' | P22: name' | Q22: , | R22: 2 | S22: ,' | T22: =Organização!G23 -> Comunicação e Conectividade | U22: '), | V22: =_xlfn.CONCAT(M22:U22) -> (112,'name',2,'Comunicação e Conectividade '),
M23: ( | N23: ='Regras de Categorização'!N23 -> 113 | O23: ,' | P23: name' | Q23: , | R23: 2 | S23: ,' | T23: =Organização!G24 -> Comunicação e Conectividade | U23: '), | V23: =_xlfn.CONCAT(M23:U23) -> (113,'name',2,'Comunicação e Conectividade '),
M24: ( | N24: ='Regras de Categorização'!N24 -> 114 | O24: ,' | P24: name' | Q24: , | R24: 2 | S24: ,' | T24: =Organização!G25 -> Comunicação e Conectividade | U24: '), | V24: =_xlfn.CONCAT(M24:U24) -> (114,'name',2,'Comunicação e Conectividade '),
M25: ( | N25: ='Regras de Categorização'!N25 -> 115 | O25: ,' | P25: name' | Q25: , | R25: 2 | S25: ,' | T25: =Organização!G26 -> Comunicação e Conectividade | U25: '), | V25: =_xlfn.CONCAT(M25:U25) -> (115,'name',2,'Comunicação e Conectividade '),
A26: Pattern é o contéudo do critério, se estamos utilizando algo já gravado no GLPI e com a condição É, Não É, esse objeto possuirá um ID, então utilizaremos o ID. Exemplo Grupo É infraestrutura, vamos aplicar o ID do grupo. Se buscamos pelo contém ou não contem, vamos utilizar o texto "Infraestrutura". | G26: Lembre-se textos precisam estar entre apóstrofes (' '). Então fique atendo a mudanças entre textos e IDs. | M26: ( | N26: ='Regras de Categorização'!N26 -> 116 | O26: ,' | P26: name' | Q26: , | R26: 2 | S26: ,' | T26: =Organização!G27 -> Comunicação e Conectividade | U26: '), | V26: =_xlfn.CONCAT(M26:U26) -> (116,'name',2,'Comunicação e Conectividade '),
M27: ( | N27: ='Regras de Categorização'!N27 -> 117 | O27: ,' | P27: name' | Q27: , | R27: 2 | S27: ,' | T27: =Organização!G28 -> Comunicação e Conectividade | U27: '), | V27: =_xlfn.CONCAT(M27:U27) -> (117,'name',2,'Comunicação e Conectividade '),
M28: ( | N28: ='Regras de Categorização'!N28 -> 118 | O28: ,' | P28: name' | Q28: , | R28: 2 | S28: ,' | T28: =Organização!G29 -> Comunicação e Conectividade | U28: '), | V28: =_xlfn.CONCAT(M28:U28) -> (118,'name',2,'Comunicação e Conectividade '),
M29: ( | N29: ='Regras de Categorização'!N29 -> 119 | O29: ,' | P29: name' | Q29: , | R29: 2 | S29: ,' | T29: =Organização!G30 -> Comunicação e Conectividade | U29: '), | V29: =_xlfn.CONCAT(M29:U29) -> (119,'name',2,'Comunicação e Conectividade '),
M30: ( | N30: ='Regras de Categorização'!N30 -> 120 | O30: ,' | P30: name' | Q30: , | R30: 2 | S30: ,' | T30: =Organização!G31 -> Comunicação e Conectividade | U30: '), | V30: =_xlfn.CONCAT(M30:U30) -> (120,'name',2,'Comunicação e Conectividade '),
M31: ( | N31: ='Regras de Categorização'!N31 -> 121 | O31: ,' | P31: name' | Q31: , | R31: 2 | S31: ,' | T31: =Organização!G32 -> Comunicação e Conectividade | U31: '), | V31: =_xlfn.CONCAT(M31:U31) -> (121,'name',2,'Comunicação e Conectividade '),
M32: ( | N32: ='Regras de Categorização'!N32 -> 122 | O32: ,' | P32: name' | Q32: , | R32: 2 | S32: ,' | T32: =Organização!G33 -> Comunicação e Conectividade | U32: '), | V32: =_xlfn.CONCAT(M32:U32) -> (122,'name',2,'Comunicação e Conectividade '),
M33: ( | N33: ='Regras de Categorização'!N33 -> 123 | O33: ,' | P33: name' | Q33: , | R33: 2 | S33: ,' | T33: =Organização!G34 -> Comunicação e Conectividade | U33: '), | V33: =_xlfn.CONCAT(M33:U33) -> (123,'name',2,'Comunicação e Conectividade '),
M34: ( | N34: ='Regras de Categorização'!N34 -> 124 | O34: ,' | P34: name' | Q34: , | R34: 2 | S34: ,' | T34: =Organização!G35 -> Comunicação e Conectividade | U34: '), | V34: =_xlfn.CONCAT(M34:U34) -> (124,'name',2,'Comunicação e Conectividade '),
A35: No exemplo ao lado estamos aplicando os critérios Título contém e Descrição contém. Então Título contém "Comunicação e Conectividade", Descrição contém "Conectividade de Internet" e "Bloqueio de Acesso a Sites" | G35: Note que o Rules_ID vai se repetir sempre que ele finalizar uma estrutura de critérios para todas as regras. Então se temos 3 critéiros, teremso 3 repetições de estutura. | M35: ( | N35: ='Regras de Categorização'!N35 -> 125 | O35: ,' | P35: name' | Q35: , | R35: 2 | S35: ,' | T35: =Organização!G36 -> Comunicação e Conectividade | U35: '), | V35: =_xlfn.CONCAT(M35:U35) -> (125,'name',2,'Comunicação e Conectividade '),
M36: ( | N36: ='Regras de Categorização'!N36 -> 126 | O36: ,' | P36: name' | Q36: , | R36: 2 | S36: ,' | T36: =Organização!G37 -> Comunicação e Conectividade | U36: '), | V36: =_xlfn.CONCAT(M36:U36) -> (126,'name',2,'Comunicação e Conectividade '),
M37: ( | N37: ='Regras de Categorização'!N37 -> 127 | O37: ,' | P37: name' | Q37: , | R37: 2 | S37: ,' | T37: =Organização!G38 -> Comunicação e Conectividade | U37: '), | V37: =_xlfn.CONCAT(M37:U37) -> (127,'name',2,'Comunicação e Conectividade '),
M38: ( | N38: ='Regras de Categorização'!N38 -> 128 | O38: ,' | P38: name' | Q38: , | R38: 2 | S38: ,' | T38: =Organização!G39 -> Comunicação e Conectividade | U38: '), | V38: =_xlfn.CONCAT(M38:U38) -> (128,'name',2,'Comunicação e Conectividade '),
M39: ( | N39: ='Regras de Categorização'!N10 -> 100 | O39: ,' | P39: content' | Q39: , | R39: 2 | S39: , | T39: =Organização!H11 -> Conectividade de Internet | U39: '), | V39: =_xlfn.CONCAT(M39:U39) -> (100,'content',2,Conectividade de Internet '),
M40: ( | N40: ='Regras de Categorização'!N11 -> 101 | O40: ,' | P40: content' | Q40: , | R40: 2 | S40: , | T40: =Organização!H12 -> Conectividade de Internet | U40: '), | V40: =_xlfn.CONCAT(M40:U40) -> (101,'content',2,Conectividade de Internet '),
M41: ( | N41: ='Regras de Categorização'!N12 -> 102 | O41: ,' | P41: content' | Q41: , | R41: 2 | S41: , | T41: =Organização!H13 -> Conectividade de Internet | U41: '), | V41: =_xlfn.CONCAT(M41:U41) -> (102,'content',2,Conectividade de Internet '),
M42: ( | N42: ='Regras de Categorização'!N13 -> 103 | O42: ,' | P42: content' | Q42: , | R42: 2 | S42: , | T42: =Organização!H14 -> Serviço de VPN | U42: '), | V42: =_xlfn.CONCAT(M42:U42) -> (103,'content',2,Serviço de VPN '),
M43: ( | N43: ='Regras de Categorização'!N14 -> 104 | O43: ,' | P43: content' | Q43: , | R43: 2 | S43: , | T43: =Organização!H15 -> Serviço de VPN | U43: '), | V43: =_xlfn.CONCAT(M43:U43) -> (104,'content',2,Serviço de VPN '),
M44: ( | N44: ='Regras de Categorização'!N15 -> 105 | O44: ,' | P44: content' | Q44: , | R44: 2 | S44: , | T44: =Organização!H16 -> Serviço de VPN | U44: '), | V44: =_xlfn.CONCAT(M44:U44) -> (105,'content',2,Serviço de VPN '),
M45: ( | N45: ='Regras de Categorização'!N16 -> 106 | O45: ,' | P45: content' | Q45: , | R45: 2 | S45: , | T45: =Organização!H17 -> Serviços de Colaboração | U45: '), | V45: =_xlfn.CONCAT(M45:U45) -> (106,'content',2,Serviços de Colaboração '),
M46: ( | N46: ='Regras de Categorização'!N17 -> 107 | O46: ,' | P46: content' | Q46: , | R46: 2 | S46: , | T46: =Organização!H18 -> Serviços de Colaboração | U46: '), | V46: =_xlfn.CONCAT(M46:U46) -> (107,'content',2,Serviços de Colaboração '),
...

Sheet Ações
V8: Insert into glpi_ruleactions
A9: Vamos aplicar as ações em ordem da primeira ação para todas as regras, depois a segunda ação, a terceira e assim sucessivamente. | G9: Não vamos utilziar o ID da ação, mas o ID de referênca da regra (rules_id) | M9: ( | N9: rule_id | O9: , | P9: action_type | Q9: , | R9: `field` | S9: , | T9: value | U9: ) | V9: =_xlfn.CONCAT(M9:U9) -> (rule_id,action_type,`field`,value)
V10: values
M11: ( | N11: ='Regras de Categorização'!N10 -> 100 | O11: ,' | P11: assign' | Q11: ,' | R11: itilcategories_id' | S11: , | T11: ='Base de Dados'!B8 -> 10 | U11: '), | V11: =_xlfn.CONCAT(M11:U11) -> (100,'assign','itilcategories_id',10 '),
M12: ( | N12: ='Regras de Categorização'!N11 -> 101 | O12: ,' | P12: assign' | Q12: ,' | R12: itilcategories_id' | S12: , | T12: ='Base de Dados'!B9 -> 12 | U12: '), | V12: =_xlfn.CONCAT(M12:U12) -> (101,'assign','itilcategories_id',12 '),
M13: ( | N13: ='Regras de Categorização'!N12 -> 102 | O13: ,' | P13: assign' | Q13: ,' | R13: itilcategories_id' | S13: , | T13: ='Base de Dados'!B10 -> 15 | U13: '), | V13: =_xlfn.CONCAT(M13:U13) -> (102,'assign','itilcategories_id',15 '),
M14: ( | N14: ='Regras de Categorização'!N13 -> 103 | O14: ,' | P14: assign' | Q14: ,' | R14: itilcategories_id' | S14: , | T14: ='Base de Dados'!B11 -> 9 | U14: '), | V14: =_xlfn.CONCAT(M14:U14) -> (103,'assign','itilcategories_id',9 '),
M15: ( | N15: ='Regras de Categorização'!N14 -> 104 | O15: ,' | P15: assign' | Q15: ,' | R15: itilcategories_id' | S15: , | T15: ='Base de Dados'!B12 -> 3 | U15: '), | V15: =_xlfn.CONCAT(M15:U15) -> (104,'assign','itilcategories_id',3 '),
M16: ( | N16: ='Regras de Categorização'!N15 -> 105 | O16: ,' | P16: assign' | Q16: ,' | R16: itilcategories_id' | S16: , | T16: ='Base de Dados'!B13 -> 25 | U16: '), | V16: =_xlfn.CONCAT(M16:U16) -> (105,'assign','itilcategories_id',25 '),
M17: ( | N17: ='Regras de Categorização'!N16 -> 106 | O17: ,' | P17: assign' | Q17: ,' | R17: itilcategories_id' | S17: , | T17: ='Base de Dados'!B14 -> 67 | U17: '), | V17: =_xlfn.CONCAT(M17:U17) -> (106,'assign','itilcategories_id',67 '),
A18: Action_Type é o tipo de ação que será aplicada, como atribuição (assign), adição (append), grupo padrão do usuário (defaultfromuser), para saber mais tipo, vá aplicando as ações e consultando o que é apresentado no banco. | G18: Field é qual o campo será aplicado na ação, com no exemplo de categorização, vamos usar itilcatetgories_id, para prioridade usamos priority, para SLAs de Solução usamos slas_id_ttr. Para outras ações consulte o banco de dados. | M18: ( | N18: ='Regras de Categorização'!N17 -> 107 | O18: ,' | P18: assign' | Q18: ,' | R18: itilcategories_id' | S18: , | T18: ='Base de Dados'!B15 -> 90 | U18: '), | V18: =_xlfn.CONCAT(M18:U18) -> (107,'assign','itilcategories_id',90 '),
M19: ( | N19: ='Regras de Categorização'!N18 -> 108 | O19: ,' | P19: assign' | Q19: ,' | R19: itilcategories_id' | S19: , | T19: ='Base de Dados'!B16 -> 34 | U19: '), | V19: =_xlfn.CONCAT(M19:U19) -> (108,'assign','itilcategories_id',34 '),
M20: ( | N20: ='Regras de Categorização'!N19 -> 109 | O20: ,' | P20: assign' | Q20: ,' | R20: itilcategories_id' | S20: , | T20: ='Base de Dados'!B17 -> 13 | U20: '), | V20: =_xlfn.CONCAT(M20:U20) -> (109,'assign','itilcategories_id',13 '),
M21: ( | N21: ='Regras de Categorização'!N20 -> 110 | O21: ,' | P21: assign' | Q21: ,' | R21: itilcategories_id' | S21: , | T21: ='Base de Dados'!B18 -> 39 | U21: '), | V21: =_xlfn.CONCAT(M21:U21) -> (110,'assign','itilcategories_id',39 '),
M22: ( | N22: ='Regras de Categorização'!N21 -> 111 | O22: ,' | P22: assign' | Q22: ,' | R22: itilcategories_id' | S22: , | T22: ='Base de Dados'!B19 -> 19 | U22: '), | V22: =_xlfn.CONCAT(M22:U22) -> (111,'assign','itilcategories_id',19 '),
M23: ( | N23: ='Regras de Categorização'!N22 -> 112 | O23: ,' | P23: assign' | Q23: ,' | R23: itilcategories_id' | S23: , | T23: ='Base de Dados'!B20 -> 21 | U23: '), | V23: =_xlfn.CONCAT(M23:U23) -> (112,'assign','itilcategories_id',21 '),
M24: ( | N24: ='Regras de Categorização'!N23 -> 113 | O24: ,' | P24: assign' | Q24: ,' | R24: itilcategories_id' | S24: , | T24: ='Base de Dados'!B21 -> 24 | U24: '), | V24: =_xlfn.CONCAT(M24:U24) -> (113,'assign','itilcategories_id',24 '),
M25: ( | N25: ='Regras de Categorização'!N24 -> 114 | O25: ,' | P25: assign' | Q25: ,' | R25: itilcategories_id' | S25: , | T25: ='Base de Dados'!B22 -> 18 | U25: '), | V25: =_xlfn.CONCAT(M25:U25) -> (114,'assign','itilcategories_id',18 '),
M26: ( | N26: ='Regras de Categorização'!N25 -> 115 | O26: ,' | P26: assign' | Q26: ,' | R26: itilcategories_id' | S26: , | T26: ='Base de Dados'!B23 -> 76 | U26: '), | V26: =_xlfn.CONCAT(M26:U26) -> (115,'assign','itilcategories_id',76 '),
A27: Em Value utilizaremos o ID do objeto da ação, como na aplicação de uma categoria, usaremos o ID da categoria, do SLA o ID do SLA que queremos aplicar. | G27: Lembre-se que as ações serão basicamente IDs entaõ não será aprecisar aplicar o ID dentro das apostrofes (' '). Fique atendo as mudanças. | M27: ( | N27: ='Regras de Categorização'!N26 -> 116 | O27: ,' | P27: assign' | Q27: ,' | R27: itilcategories_id' | S27: , | T27: ='Base de Dados'!B24 -> 89 | U27: '), | V27: =_xlfn.CONCAT(M27:U27) -> (116,'assign','itilcategories_id',89 '),
M28: ( | N28: ='Regras de Categorização'!N27 -> 117 | O28: ,' | P28: assign' | Q28: ,' | R28: itilcategories_id' | S28: , | T28: ='Base de Dados'!B25 -> 66 | U28: '), | V28: =_xlfn.CONCAT(M28:U28) -> (117,'assign','itilcategories_id',66 '),
M29: ( | N29: ='Regras de Categorização'!N28 -> 118 | O29: ,' | P29: assign' | Q29: ,' | R29: itilcategories_id' | S29: , | T29: ='Base de Dados'!B26 -> 14 | U29: '), | V29: =_xlfn.CONCAT(M29:U29) -> (118,'assign','itilcategories_id',14 '),
M30: ( | N30: ='Regras de Categorização'!N29 -> 119 | O30: ,' | P30: assign' | Q30: ,' | R30: itilcategories_id' | S30: , | T30: ='Base de Dados'!B27 -> 17 | U30: '), | V30: =_xlfn.CONCAT(M30:U30) -> (119,'assign','itilcategories_id',17 '),
M31: ( | N31: ='Regras de Categorização'!N30 -> 120 | O31: ,' | P31: assign' | Q31: ,' | R31: itilcategories_id' | S31: , | T31: ='Base de Dados'!B28 -> 11 | U31: '), | V31: =_xlfn.CONCAT(M31:U31) -> (120,'assign','itilcategories_id',11 '),
M32: ( | N32: ='Regras de Categorização'!N31 -> 121 | O32: ,' | P32: assign' | Q32: ,' | R32: itilcategories_id' | S32: , | T32: ='Base de Dados'!B29 -> 5 | U32: '), | V32: =_xlfn.CONCAT(M32:U32) -> (121,'assign','itilcategories_id',5 '),
M33: ( | N33: ='Regras de Categorização'!N32 -> 122 | O33: ,' | P33: assign' | Q33: ,' | R33: itilcategories_id' | S33: , | T33: ='Base de Dados'!B30 -> 27 | U33: '), | V33: =_xlfn.CONCAT(M33:U33) -> (122,'assign','itilcategories_id',27 '),
M34: ( | N34: ='Regras de Categorização'!N33 -> 123 | O34: ,' | P34: assign' | Q34: ,' | R34: itilcategories_id' | S34: , | T34: ='Base de Dados'!B31 -> 1 | U34: '), | V34: =_xlfn.CONCAT(M34:U34) -> (123,'assign','itilcategories_id',1 '),
M35: ( | N35: ='Regras de Categorização'!N34 -> 124 | O35: ,' | P35: assign' | Q35: ,' | R35: itilcategories_id' | S35: , | T35: ='Base de Dados'!B32 -> 91 | U35: '), | V35: =_xlfn.CONCAT(M35:U35) -> (124,'assign','itilcategories_id',91 '),
A36: Faça o vinculo do Value com o ID da categoria na primeira guia desse tutorial, Base de Dados. | G36: Agora faça você a aplicação dos SLAs e Grupos com base nesse tutorial. | M36: ( | N36: ='Regras de Categorização'!N35 -> 125 | O36: ,' | P36: assign' | Q36: ,' | R36: itilcategories_id' | S36: , | T36: ='Base de Dados'!B33 -> 65 | U36: '), | V36: =_xlfn.CONCAT(M36:U36) -> (125,'assign','itilcategories_id',65 '),
M37: ( | N37: ='Regras de Categorização'!N36 -> 126 | O37: ,' | P37: assign' | Q37: ,' | R37: itilcategories_id' | S37: , | T37: ='Base de Dados'!B34 -> 83 | U37: '), | V37: =_xlfn.CONCAT(M37:U37) -> (126,'assign','itilcategories_id',83 '),
M38: ( | N38: ='Regras de Categorização'!N37 -> 127 | O38: ,' | P38: assign' | Q38: ,' | R38: itilcategories_id' | S38: , | T38: ='Base de Dados'!B35 -> 77 | U38: '), | V38: =_xlfn.CONCAT(M38:U38) -> (127,'assign','itilcategories_id',77 '),
M39: ( | N39: ='Regras de Categorização'!N38 -> 128 | O39: ,' | P39: assign' | Q39: ,' | R39: itilcategories_id' | S39: , | T39: ='Base de Dados'!B36 -> 44 | U39: '), | V39: =_xlfn.CONCAT(M39:U39) -> (128,'assign','itilcategories_id',44 '),
M41: Copie o insert acima no seu SQL, lembre-se de sempre ter realizado um backup antes, seja da tabela ou do banco de dados inteiro. Antes de executar dê o comando crtl+F para abrir a janela de pesquisa e substituição. Substitua " '," (espaço+apostrofe+virgula), por "'," (apostrofe+virgula). Removendo o espaço que ficou entre o final do nome da regra e a próxima instrução.
XFD1048576: Essa planilha foi desenvolvida pela Servicedesk Brasil e sua publicação ou venda é expressamente proíbida.

Sheet Regras de SLA
V8: insert into glpi_rules
A9: ( | B9: id | C9: , | D9: entities_id | E9: , | F9: sub_type | G9: , | H9: ranking | I9: , | J9: name | K9: , | L9: description | M9: , | N9: `match` | O9: , | P9: is_active | Q9: , | R9: is_recursive | S9: , | T9: condition | U9: ) | V9: =_xlfn.CONCAT(A9:U9) -> (id,entities_id,sub_type,ranking,name,description,`match`,is_active,is_recursive,condition)
V10: Values
A11: ( | B11: 129 | C11: , | D11: 0 | E11: ,' | F11: RuleTicket' | G11: , | I11: ,' | J11: SLA de Solução 04 horas x Categorias | K11: ',' | L11: regra para atribuição do SLA conforme a categoria do chamado' | M11: ,' | N11: AND' | O11: , | P11: 1 | Q11: , | R11: 1 | S11: , | T11: 1 | U11: ), | V11: =_xlfn.CONCAT(A11:U11) -> (129,0,'RuleTicket',,'SLA de Solução 04 horas x Categorias ','regra para atribuição do SLA conforme a categoria do chamado','AND',1,1,1),
A12: ( | B12: =B11+1 -> 130 | C12: , | D12: 0 | E12: ,' | G12: , | I12: ,' | K12: ',' | M12: ,' | O12: , | Q12: , | S12: , | U12: ), | V12: =_xlfn.CONCAT(A12:U12) -> (130,0,',,' ',',',,,),
A13: ( | B13: =B12+1 -> 131 | C13: , | D13: 0 | E13: ,' | G13: , | I13: ,' | K13: ',' | M13: ,' | O13: , | Q13: , | S13: , | U13: ), | V13: =_xlfn.CONCAT(A13:U13) -> (131,0,',,' ',',',,,),
A14: ( | B14: =B13+1 -> 132 | C14: , | D14: 0 | E14: ,' | G14: , | I14: ,' | K14: ',' | M14: ,' | O14: , | Q14: , | S14: , | U14: ), | V14: =_xlfn.CONCAT(A14:U14) -> (132,0,',,' ',',',,,),
V16: Copie o insert acima no seu SQL, lembre-se de sempre ter realizado um backup antes, seja da tabela ou do banco de dados inteiro. Antes de executar dê o comando crtl+F para abrir a janela de pesquisa e substituição. Substitua " '," (espaço+apostrofe+virgula), por "'," (apostrofe+virgula). Removendo o espaço que ficou entre o final do nome da regra e a próxima instrução.
XFD1048576: Essa planilha foi desenvolvida pela Servicedesk Brasil e sua publicação ou venda é expressamente proíbida.

Sheet Critérios de SLA
K9: Insert into glpi_rulecriterias
B10: ( | C10: rule_id | D10: , | E10: critéria | F10: , | G10: condition | H10: , | I10: pattern | J10: ) | K10: =_xlfn.CONCAT(B10:J10) -> (rule_id,critéria,condition,pattern)
K11: values
B12: ( | C12: ='Regras de SLA'!B11 -> 129 | D12: ,' | E12: itilcategories_id' | F12: , | G12: 0 | H12: , | I12: ='Base de Dados'!B9 -> 12 | J12: ), | K12: =_xlfn.CONCAT(B12:J12) -> (129,'itilcategories_id',0,12),
B13: ( | D13: ,' | F13: , | H13: , | J13: ),
B14: ( | D14: ,' | F14: , | H14: , | J14: ),
B15: ( | D15: ,' | F15: , | H15: , | J15: ),
B16: ( | D16: ,' | F16: , | H16: , | J16: ),
B17: ( | D17: ,' | F17: , | H17: , | J17: ),
B18: ( | D18: ,' | F18: , | H18: , | J18: ),
B19: ( | D19: ,' | F19: , | H19: , | J19: ),
B20: ( | D20: ,' | F20: , | H20: , | J20: ),
B21: ( | D21: ,' | F21: , | H21: , | J21: ),
B22: ( | D22: ,' | F22: , | H22: , | J22: ),
B23: ( | D23: ,' | F23: , | H23: , | J23: ),
B24: ( | D24: ,' | F24: , | H24: , | J24: ),
... B37: ( | D37: ,' | F37: , | H37: , | J37: ),
B39: Copie o insert acima no seu SQL, lembre-se de sempre ter realizado um backup antes, seja da tabela ou do banco de dados inteiro. Antes de executar dê o comando crtl+F para abrir a janela de pesquisa e substituição. Substitua " '," (espaço+apostrofe+virgula), por "'," (apostrofe+virgula). Removendo o espaço que ficou entre o final do nome da regra e a próxima instrução.
XFD1048576: Essa planilha foi desenvolvida pela Servicedesk Brasil e sua publicação ou venda é expressamente proíbida.

Sheet Ações de SLA
K9: Insert into glpi_ruleactions
B10: ( | C10: rule_id | D10: , | E10: action_type | F10: , | G10: `field` | H10: , | I10: value | J10: ) | K10: =_xlfn.CONCAT(B10:J10) -> (rule_id,action_type,`field`,value)
K11: values
B12: ( | C12: ='Regras de SLA'!B11 -> 129 | D12: ,' | E12: assign' | F12: ,' | G12: slas_id_ttr' | H12: , | I12: ='Base de Dados'!D9 -> 12 | J12: ), | K12: =_xlfn.CONCAT(B12:J12) -> (129,'assign','slas_id_ttr',12),
B13: ( | D13: ,' | F13: ,' | H13: , | J13: ), | K13: =_xlfn.CONCAT(B13:J13) -> (,',',),
B14: ( | D14: ,' | F14: ,' | H14: , | J14: ), | K14: =_xlfn.CONCAT(B14:J14) -> (,',',),
B15: ( | D15: ,' | F15: ,' | H15: , | J15: ), | K15: =_xlfn.CONCAT(B15:J15) -> (,',',),
B16: ( | D16: ,' | F16: ,' | H16: , | J16: ), | K16: =_xlfn.CONCAT(B16:J16) -> (,',',),
B17: ( | D17: ,' | F17: ,' | H17: , | J17: ), | K17: =_xlfn.CONCAT(B17:J17) -> (,',',),
B18: ( | D18: ,' | F18: ,' | H18: , | J18: ), | K18: =_xlfn.CONCAT(B18:J18) -> (,',',),
B19: ( | D19: ,' | F19: ,' | H19: , | J19: ), | K19: =_xlfn.CONCAT(B19:J19) -> (,',',),
